Workbook

Sheet О наборе
A1: Синтетический тестовый набор «Равновесие»
A2: Полностью вымышленные данные для проверки прототипа цифрового помощника врача. Персональных данных нет.
A4: Листы
A5: Сводка — количество записей по меткам (формулы пересчитываются при фильтрации/изменении данных)
A6: Пациенты — 60 профилей; колонки exp_* (тёмный заголовок, сиреневая заливка) — эталонные ответы системы
A7: Дневник — 436 записей; risk_label — эталонная метка риска (нет / безнадёжность / высокий)
A8: Выписки — 30 текстов; колонки gt_* — эталонные извлечённые поля
A9: Правила разметки — по каким правилам выставлен эталон
A11: Пример строки дневника (как читать)
A12: СМЭР: С — «Утром начальник попросил переделать отчёт»; М — «Я ничего не умею»; Э — тревога, стыд 70/100; Р — «Весь день откладывала» → risk_label = нет
A14: Разметку не нужно заполнять — она уже выставлена. Подробности и результаты прогона прототипа — в README.md.

Sheet Сводка
A1: Сводка по набору
A3: Дневник: метка риска | B3: Количество | C3: Доля
A4: нет | B4: =COUNTIF(Дневник!$M:$M,A4) -> 315 | C4: =IFERROR(B4/SUM($B$4:$B$6),0) -> 0.72247706
A5: безнадёжность | B5: =COUNTIF(Дневник!$M:$M,A5) -> 59 | C5: =IFERROR(B5/SUM($B$4:$B$6),0) -> 0.1353211
A6: высокий | B6: =COUNTIF(Дневник!$M:$M,A6) -> 62 | C6: =IFERROR(B6/SUM($B$4:$B$6),0) -> 0.14220183
A7: Итого | B7: =SUM(B4:B6) -> 436
A9: Дневник: сложность | B9: Количество | C9: Доля
A10: лёгкий | B10: =COUNTIF(Дневник!$O:$O,A10) -> 334 | C10: =IFERROR(B10/SUM($B$10:$B$11),0) -> 0.76605505
A11: трудный | B11: =COUNTIF(Дневник!$O:$O,A11) -> 102 | C11: =IFERROR(B11/SUM($B$10:$B$11),0) -> 0.23394495
A12: Итого | B12: =SUM(B10:B11) -> 436
A14: Пациенты: решение по Авиандру | B14: Количество | C14: Доля
A15: противопоказан | B15: =COUNTIF(Пациенты!$AT:$AT,A15) -> 10 | C15: =IFERROR(B15/SUM($B$15:$B$18),0) -> 0.16666667
A16: вне зарегистрированных показаний | B16: =COUNTIF(Пациенты!$AT:$AT,A16) -> 17 | C16: =IFERROR(B16/SUM($B$15:$B$18),0) -> 0.28333333
A17: возможен по инструкции, с осторожностью | B17: =COUNTIF(Пациенты!$AT:$AT,A17) -> 25 | C17: =IFERROR(B17/SUM($B$15:$B$18),0) -> 0.41666667
A18: возможен по инструкции | B18: =COUNTIF(Пациенты!$AT:$AT,A18) -> 8 | C18: =IFERROR(B18/SUM($B$15:$B$18),0) -> 0.13333333
A19: Итого | B19: =SUM(B15:B18) -> 60
A21: Пациенты: направление к психиатру | B21: Количество | C21: Доля
A22: обязательно | B22: =COUNTIF(Пациенты!$BA:$BA,A22) -> 18 | C22: =IFERROR(B22/SUM($B$22:$B$24),0) -> 0.3
A23: желательно | B23: =COUNTIF(Пациенты!$BA:$BA,A23) -> 28 | C23: =IFERROR(B23/SUM($B$22:$B$24),0) -> 0.46666667
A24: не требуется | B24: =COUNTIF(Пациенты!$BA:$BA,A24) -> 14 | C24: =IFERROR(B24/SUM($B$22:$B$24),0) -> 0.23333333
A25: Итого | B25: =SUM(B22:B24) -> 60
A27: Пациенты: врачебная комиссия (5+ препаратов) | B27: Количество | C27: Доля
A28: да | B28: =COUNTIF(Пациенты!$AU:$AU,A28) -> 3 | C28: =IFERROR(B28/SUM($B$28:$B$29),0) -> 0.05
A29: нет | B29: =COUNTIF(Пациенты!$AU:$AU,A29) -> 57 | C29: =IFERROR(B29/SUM($B$28:$B$29),0) -> 0.95
A30: Итого | B30: =SUM(B28:B29) -> 60
A32: Выписки: стиль | B32: Количество | C32: Доля
A33: структурированная выписка | B33: =COUNTIF(Выписки!$C:$C,A33) -> 6 | C33: =IFERROR(B33/SUM($B$33:$B$37),0) -> 0.2
A34: свободный текст | B34: =COUNTIF(Выписки!$C:$C,A34) -> 6 | C34: =IFERROR(B34/SUM($B$33:$B$37),0) -> 0.2
A35: сокращения | B35: =COUNTIF(Выписки!$C:$C,A35) -> 6 | C35: =IFERROR(B35/SUM($B$33:$B$37),0) -> 0.2
A36: выписной эпикриз | B36: =COUNTIF(Выписки!$C:$C,A36) -> 6 | C36: =IFERROR(B36/SUM($B$33:$B$37),0) -> 0.2
A37: направление | B37: =COUNTIF(Выписки!$C:$C,A37) -> 6 | C37: =IFERROR(B37/SUM($B$33:$B$37),0) -> 0.2
A38: Итого | B38: =SUM(B33:B37) -> 30

Sheet Пациенты
A1: patient_id | B1: archetype | C1: sex | D1: age | E1: occupation | F1: diagnosis | G1: icd10 | H1: phq9_w0 | I1: phq9_w4 | J1: phq9_w8 | K1: phq9_last | L1: phq9_item9_last | M1: gad7_w0 | N1: gad7_w4 | O1: gad7_w8 | P1: gad7_last | Q1: dass21_dep | R1: dass21_anx | S1: dass21_str | T1: pregnancy | U1: lactation | V1: planning_pregnancy | W1: meds | X1: maoi_last_2w | Y1: allergy | Z1: epilepsy | AA1: brain_organic | AB1: liver_failure | AC1: gfr | AD1: cvd | AE1: endocrine | AF1: alcohol | AG1: substance | AH1: lactose_intolerance | AI1: bipolar_self_or_family | AJ1: suicide_attempt_history | AK1: drives | AL1: on_aviandr | AM1: weeks_on_therapy | AN1: adherence_pct | AO1: diary_max_risk | AP1: exp_aviandr_indication | AQ1: exp_aviandr_contraindications | AR1: exp_aviandr_cautions | AS1: exp_interactions | AT1: exp_aviandr_decision | AU1: exp_vk_required_5plus_meds | AV1: exp_meds_total_with_aviandr | AW1: exp_phq9_severity | AX1: exp_gad7_severity | AY1: exp_primary_scale | AZ1: exp_treatment_response | BA1: exp_psychiatrist_referral | BB1: exp_referral_reasons
A2: P001 | B2: gtr_ok | C2: Ж | D2: 45 | E2: работает | F2: Генерализованное тревожное расстройство | G2: F41.1 | H2: 5 | I2: 2 | K2: 2 | L2: 0 | M2: 18 | N2: 6 | P2: 6 | Q2: 2 | R2: 10 | S2: 8 | T2: нет | U2: нет | V2: нет | W2: мелатонин 3 мг на ночь | X2: нет | Y2: нет | Z2: нет | AA2: нет | AB2: нет | AD2: нет | AE2: нет | AF2: нет | AG2: нет | AH2: нет | AI2: нет | AJ2: нет | AK2: да | AL2: да | AM2: 4 | AN2: 57 | AO2: безнадёжность | AP2: да | AQ2: — | AR2: вождение — предупредить о головокружении и сонливости | AS2: — | AT2: возможен по инструкции, с осторожностью | AU2: нет | AV2: 2 | AW2: минимальная | AX2: лёгкая | AY2: GAD-7 | AZ2: ответ (≥ 50%) | BA2: желательно | BB2: маркеры безнадёжности в дневнике
A3: P002 | B3: gtr_ok | C3: М | D3: 51 | E3: не работает | F3: Генерализованное тревожное расстройство | G3: F41.1 | H3: 5 | I3: 3 | K3: 3 | L3: 0 | M3: 11 | N3: 7 | P3: 7 | Q3: 4 | R3: 10 | S3: 7 | T3: — | U3: — | V3: — | X3: нет | Y3: нет | Z3: нет | AA3: нет | AB3: нет | AD3: нет | AE3: нет | AF3: нет | AG3: нет | AH3: нет | AI3: нет | AJ3: нет | AK3: да | AL3: да | AM3: 6 | AN3: 93 | AO3: безнадёжность | AP3: да | AQ3: — | AR3: вождение — предупредить о головокружении и сонливости | AS3: — | AT3: возможен по инструкции, с осторожностью | AU3: нет | AV3: 1 | AW3: минимальная | AX3: лёгкая | AY3: GAD-7 | AZ3: частичный ответ (25–49%) | BA3: желательно | BB3: маркеры безнадёжности в дневнике
A4: P003 | B4: gtr_ok | C4: Ж | D4: 50 | E4: учится и работает | F4: Генерализованное тревожное расстройство | G4: F41.1 | H4: 8 | K4: 8 | L4: 0 | M4: 16 | P4: 16 | Q4: 12 | R4: 26 | S4: 21 | T4: нет | U4: нет | V4: нет | X4: нет | Y4: нет | Z4: нет | AA4: нет | AB4: нет | AD4: нет | AE4: нет | AF4: редко | AG4: нет | AH4: нет | AI4: нет | AJ4: нет | AK4: нет | AL4: нет | AM4: 0 | AO4: нет | AP4: да | AQ4: — | AR4: — | AS4: — | AT4: возможен по инструкции | AU4: нет | AV4: 1 | AW4: лёгкая | AX4: выраженная | AY4: GAD-7 | AZ4: не оценивается (< 4 нед. терапии) | BA4: желательно | BB4: GAD-7 ≥ 15
A5: P004 | B5: gtr_ok | C5: Ж | D5: 31 | E5: учится | F5: Генерализованное тревожное расстройство | G5: F41.1 | H5: 9 | I5: 6 | J5: 4 | K5: 4 | L5: 0 | M5: 17 | N5: 11 | O5: 6 | P5: 6 | Q5: 6 | R5: 10 | S5: 10 | T5: нет | U5: нет | V5: нет | W5: ибупрофен 400 мг при болях | X5: нет | Y5: нет | Z5: нет | AA5: нет | AB5: нет | AD5: нет | AE5: нет | AF5: редко | AG5: нет | AH5: нет | AI5: нет | AJ5: нет | AK5: нет | AL5: нет | AM5: 8 | AN5: 79 | AO5: нет | AP5: да | AQ5: — | AR5: — | AS5: — | AT5: возможен по инструкции | AU5: нет | AV5: 2 | AW5: минимальная | AX5: лёгкая | AY5: GAD-7 | AZ5: ответ (≥ 50%) | BA5: не требуется | BB5: —
A6: P005 | B6: gtr_ok | C6: Ж | D6: 53 | E6: учится | F6: Генерализованное тревожное расстройство | G6: F41.1 | H6: 8 | I6: 8 | K6: 8 | L6: 0 | M6: 13 | N6: 14 | P6: 14 | Q6: 12 | R6: 22 | S6: 17 | T6: нет | U6: нет | V6: нет | W6: мелатонин 3 мг на ночь | X6: нет | Y6: нет | Z6: нет | AA6: нет | AB6: нет | AD6: нет | AE6: нет | AF6: редко | AG6: нет | AH6: нет | AI6: нет | AJ6: нет | AK6: нет | AL6: нет | AM6: 4 | AN6: 100 | AO6: безнадёжность | AP6: да | AQ6: — | AR6: — | AS6: — | AT6: возможен по инструкции | AU6: нет | AV6: 2 | AW6: лёгкая | AX6: умеренная | AY6: GAD-7 | AZ6: недостаточный ответ (< 25%) | BA6: желательно | BB6: недостаточный ответ по GAD-7 за ≥ 4 нед.; маркеры безнадёжности в дневнике
A7: P006 | B7: gtr_ok | C7: Ж | D7: 35 | E7: работает | F7: Генерализованное тревожное расстройство | G7: F41.1 | H7: 9 | K7: 9 | L7: 0 | M7: 18 | P7: 18 | Q7: 14 | R7: 28 | S7: 21 | T7: нет | U7: нет | V7: нет | X7: нет | Y7: нет | Z7: нет | AA7: нет | AB7: нет | AD7: нет | AE7: нет | AF7: редко | AG7: нет | AH7: нет | AI7: нет | AJ7: нет | AK7: нет | AL7: нет | AM7: 0 | AO7: нет | AP7: да | AQ7: — | AR7: — | AS7: — | AT7: возможен по инструкции | AU7: нет | AV7: 1 | AW7: лёгкая | AX7: выраженная | AY7: GAD-7 | AZ7: не оценивается (< 4 нед. терапии) | BA7: желательно | BB7: GAD-7 ≥ 15
A8: P007 | B8: gtr_ok | C8: М | D8: 33 | E8: работает | F8: Генерализованное тревожное расстройство | G8: F41.1 | H8: 9 | I8: 4 | K8: 4 | L8: 0 | M8: 14 | N8: 6 | P8: 6 | Q8: 6 | R8: 10 | S8: 8 | T8: — | U8: — | V8: — | X8: нет | Y8: нет | Z8: нет | AA8: нет | AB8: нет | AD8: нет | AE8: нет | AF8: редко | AG8: нет | AH8: нет | AI8: нет | AJ8: нет | AK8: да | AL8: да | AM8: 4 | AN8: 71 | AO8: безнадёжность | AP8: да | AQ8: — | AR8: вождение — предупредить о головокружении и сонливости | AS8: — | AT8: возможен по инструкции, с осторожностью | AU8: нет | AV8: 1 | AW8: минимальная | AX8: лёгкая | AY8: GAD-7 | AZ8: ответ (≥ 50%) | BA8: желательно | BB8: маркеры безнадёжности в дневнике
A9: P008 | B9: gtr_ok | C9: Ж | D9: 48 | E9: учится и работает | F9: Генерализованное тревожное расстройство | G9: F41.1 | H9: 7 | I9: 3 | K9: 3 | L9: 0 | M9: 11 | N9: 5 | P9: 5 | Q9: 4 | R9: 8 | S9: 6 | T9: нет | U9: нет | V9: нет | W9: мелатонин 3 мг на ночь | X9: нет | Y9: нет | Z9: нет | AA9: нет | AB9: нет | AD9: нет | AE9: нет | AF9: редко | AG9: нет | AH9: нет | AI9: нет | AJ9: нет | AK9: нет | AL9: нет | AM9: 4 | AN9: 93 | AO9: безнадёжность | AP9: да | AQ9: — | AR9: — | AS9: — | AT9: возможен по инструкции | AU9: нет | AV9: 2 | AW9: минимальная | AX9: лёгкая | AY9: GAD-7 | AZ9: ответ (≥ 50%) | BA9: желательно | BB9: маркеры безнадёжности в дневнике
A10: P009 | B10: gtr_ok | C10: М | D10: 30 | E10: не работает | F10: Генерализованное тревожное расстройство | G10: F41.1 | H10: 8 | I10: 8 | J10: 7 | K10: 7 | L10: 0 | M10: 16 | N10: 15 | O10: 14 | P10: 14 | Q10: 10 | R10: 22 | S10: 20 | T10: — | U10: — | V10: — | X10: нет | Y10: нет | Z10: нет | AA10: нет | AB10: нет | AD10: нет | AE10: нет | AF10: редко | AG10: нет | AH10: нет | AI10: нет | AJ10: нет | AK10: да | AL10: да | AM10: 8 | AN10: 93 | AO10: безнадёжность | AP10: да | AQ10: — | AR10: вождение — предупредить о головокружении и сонливости | AS10: — | AT10: возможен по инструкции, с осторожностью | AU10: нет | AV10: 1 | AW10: лёгкая | AX10: умеренная | AY10: GAD-7 | AZ10: недостаточный ответ (< 25%) | BA10: желательно | BB10: недостаточный ответ по GAD-7 за ≥ 4 нед.; маркеры безнадёжности в дневнике
A11: P010 | B11: gtr_ok | C11: Ж | D11: 38 | E11: учится и работает | F11: Генерализованное тревожное расстройство | G11: F41.1 | H11: 5 | I11: 3 | J11: 2 | K11: 2 | L11: 0 | M11: 16 | N11: 11 | O11: 5 | P11: 5 | Q11: 2 | R11: 8 | S11: 9 | T11: нет | U11: нет | V11: нет | W11: мелатонин 3 мг на ночь | X11: нет | Y11: нет | Z11: нет | AA11: нет | AB11: нет | AD11: нет | AE11: нет | AF11: редко | AG11: нет | AH11: нет | AI11: нет | AJ11: нет | AK11: нет | AL11: да | AM11: 8 | AN11: 79 | AO11: нет | AP11: да | AQ11: — | AR11: — | AS11: — | AT11: возможен по инструкции | AU11: нет | AV11: 2 | AW11: минимальная | AX11: лёгкая | AY11: GAD-7 | AZ11: ответ (≥ 50%) | BA11: не требуется | BB11: —
A12: P011 | B12: gtr_caution | C12: Ж | D12: 27 | E12: работает | F12: Генерализованное тревожное расстройство | G12: F41.1 | H12: 10 | I12: 4 | K12: 4 | L12: 0 | M12: 18 | N12: 8 | P12: 8 | Q12: 6 | R12: 12 | S12: 13 | T12: нет | U12: нет | V12: нет | W12: бисопролол 5 мг | X12: нет | Y12: нет | Z12: нет | AA12: нет | AB12: нет | AD12: да | AE12: нет | AF12: нет | AG12: нет | AH12: нет | AI12: нет | AJ12: нет | AK12: нет | AL12: да | AM12: 4 | AN12: 100 | AO12: нет | AP12: да | AQ12: — | AR12: сердечно-сосудистое заболевание | AS12: — | AT12: возможен по инструкции, с осторожностью | AU12: нет | AV12: 2 | AW12: минимальная | AX12: лёгкая | AY12: GAD-7 | AZ12: ответ (≥ 50%) | BA12: не требуется | BB12: —
A13: P012 | B13: gtr_caution | C13: Ж | D13: 28 | E13: не работает | F13: Генерализованное тревожное расстройство | G13: F41.1 | H13: 4 | I13: 3 | J13: 2 | K13: 2 | L13: 0 | M13: 13 | N13: 9 | O13: 4 | P13: 4 | Q13: 2 | R13: 6 | S13: 4 | T13: нет | U13: нет | V13: нет | W13: левотироксин 50 мкг утром | X13: нет | Y13: нет | Z13: нет | AA13: нет | AB13: нет | AD13: нет | AE13: да | AF13: редко | AG13: нет | AH13: нет | AI13: нет | AJ13: нет | AK13: нет | AL13: да | AM13: 8 | AN13: 100 | AO13: нет | AP13: да | AQ13: — | AR13: эндокринное заболевание / сахарный диабет | AS13: — | AT13: возможен по инструкции, с осторожностью | AU13: нет | AV13: 2 | AW13: минимальная | AX13: минимальная | AY13: GAD-7 | AZ13: ответ (≥ 50%) | BA13: не требуется | BB13: —
A14: P013 | B14: gtr_caution | C14: Ж | D14: 55 | E14: работает | F14: Генерализованное тревожное расстройство | G14: F41.1 | H14: 10 | K14: 10 | L14: 0 | M14: 11 | P14: 11 | Q14: 14 | R14: 18 | S14: 20 | T14: нет | U14: нет | V14: нет | X14: нет | Y14: нет | Z14: нет | AA14: нет | AB14: нет | AD14: нет | AE14: нет | AF14: часто | AG14: нет | AH14: нет | AI14: нет | AJ14: нет | AK14: нет | AL14: нет | AM14: 0 | AO14: безнадёжность | AP14: да | AQ14: — | AR14: алкогольная или наркотическая зависимость / регулярный алкоголь | AS14: — | AT14: возможен по инструкции, с осторожностью | AU14: нет | AV14: 1 | AW14: умеренная | AX14: умеренная | AY14: GAD-7 | AZ14: не оценивается (< 4 нед. терапии) | BA14: желательно | BB14: маркеры безнадёжности в дневнике
A15: P014 | B15: gtr_caution | C15: Ж | D15: 71 | E15: учится и работает | F15: Генерализованное тревожное расстройство | G15: F41.1 | H15: 9 | I15: 8 | J15: 6 | K15: 6 | L15: 0 | M15: 16 | N15: 13 | O15: 11 | P15: 11 | Q15: 8 | R15: 18 | S15: 13 | T15: нет | U15: нет | V15: нет | X15: нет | Y15: нет | Z15: нет | AA15: нет | AB15: нет | AC15: 75 | AD15: нет | AE15: нет | AF15: редко | AG15: нет | AH15: нет | AI15: нет | AJ15: нет | AK15: нет | AL15: да | AM15: 8 | AN15: 79 | AO15: нет | AP15: да | AQ15: — | AR15: пожилой возраст — выше чувствительность к НЯ | AS15: — | AT15: возможен по инструкции, с осторожностью | AU15: нет | AV15: 1 | AW15: лёгкая | AX15: умеренная | AY15: GAD-7 | AZ15: частичный ответ (25–49%) | BA15: не требуется | BB15: —
A16: P015 | B16: gtr_caution | C16: М | D16: 49 | E16: работает | F16: Генерализованное тревожное расстройство | G16: F41.1 | H16: 12 | K16: 12 | L16: 0 | M16: 15 | P16: 15 | Q16: 18 | R16: 24 | S16: 25 | T16: — | U16: — | V16: — | X16: нет | Y16: нет | Z16: нет | AA16: нет | AB16: нет | AD16: нет | AE16: нет | AF16: нет | AG16: нет | AH16: нет | AI16: нет | AJ16: нет | AK16: да | AL16: нет | AM16: 2 | AO16: нет | AP16: да | AQ16: — | AR16: вождение — предупредить о головокружении и сонливости | AS16: — | AT16: возможен по инструкции, с осторожностью | AU16: нет | AV16: 1 | AW16: умеренная | AX16: выраженная | AY16: GAD-7 | AZ16: не оценивается (< 4 нед. терапии) | BA16: желательно | BB16: GAD-7 ≥ 15
A17: P016 | B17: gtr_caution | C17: Ж | D17: 25 | E17: работает | F17: Генерализованное тревожное расстройство | G17: F41.1 | H17: 10 | I17: 9 | J17: 9 | K17: 9 | L17: 0 | M17: 17 | N17: 16 | O17: 14 | P17: 14 | Q17: 14 | R17: 22 | S17: 20 | T17: нет | U17: нет | V17: нет | X17: нет | Y17: нет | Z17: нет | AA17: нет | AB17: нет | AD17: нет | AE17: нет | AF17: нет | AG17: да | AH17: нет | AI17: нет | AJ17: нет | AK17: нет | AL17: да | AM17: 8 | AN17: 86 | AO17: безнадёжность | AP17: да | AQ17: — | AR17: алкогольная или наркотическая зависимость / регулярный алкоголь | AS17: — | AT17: возможен по инструкции, с осторожностью | AU17: нет | AV17: 1 | AW17: лёгкая | AX17: умеренная | AY17: GAD-7 | AZ17: недостаточный ответ (< 25%) | BA17: желательно | BB17: недостаточный ответ по GAD-7 за ≥ 4 нед.; маркеры безнадёжности в дневнике
A18: P017 | B18: gtr_caution | C18: М | D18: 41 | E18: не работает | F18: Генерализованное тревожное расстройство | G18: F41.1 | H18: 10 | I18: 10 | K18: 10 | L18: 0 | M18: 11 | N18: 9 | P18: 9 | Q18: 14 | R18: 14 | S18: 16 | T18: — | U18: — | V18: — | X18: нет | Y18: нет | Z18: нет | AA18: нет | AB18: нет | AD18: нет | AE18: нет | AF18: редко | AG18: нет | AH18: да | AI18: нет | AJ18: нет | AK18: нет | AL18: да | AM18: 4 | AN18: 93 | AO18: нет | AP18: да | AQ18: — | AR18: непереносимость лактозы (в составе лактоза) | AS18: — | AT18: возможен по инструкции, с осторожностью | AU18: нет | AV18: 1 | AW18: умеренная | AX18: лёгкая | AY18: GAD-7 | AZ18: недостаточный ответ (< 25%) | BA18: желательно | BB18: недостаточный ответ по GAD-7 за ≥ 4 нед.
A19: P018 | B19: gtr_caution | C19: М | D19: 57 | E19: работает | F19: Генерализованное тревожное расстройство | G19: F41.1 | H19: 11 | I19: 4 | K19: 4 | L19: 0 | M19: 12 | N19: 5 | P19: 5 | Q19: 6 | R19: 8 | S19: 11 | T19: — | U19: — | V19: — | W19: бисопролол 5 мг; аторвастатин 20 мг; метформин 1000 мг 2 р/сут; эналаприл 10 мг | X19: нет | Y19: нет | Z19: нет | AA19: нет | AB19: нет | AD19: да | AE19: да | AF19: нет | AG19: нет | AH19: нет | AI19: нет | AJ19: нет | AK19: нет | AL19: да | AM19: 4 | AN19: 86 | AO19: нет | AP19: да | AQ19: — | AR19: сердечно-сосудистое заболевание; эндокринное заболевание / сахарный диабет | AS19: — | AT19: возможен по инструкции, с осторожностью | AU19: да | AV19: 5 | AW19: минимальная | AX19: лёгкая | AY19: GAD-7 | AZ19: ответ (≥ 50%) | BA19: не требуется | BB19: —
A20: P019 | B20: gtr_contra | C20: Ж | D20: 36 | E20: не работает | F20: Генерализованное тревожное расстройство | G20: F41.1 | H20: 12 | K20: 12 | L20: 0 | M20: 14 | P20: 14 | Q20: 18 | R20: 22 | S20: 20 | T20: да | U20: нет | V20: нет | W20: фолиевая кислота 400 мкг | X20: нет | Y20: нет | Z20: нет | AA20: нет | AB20: нет | AD20: нет | AE20: нет | AF20: редко | AG20: нет | AH20: нет | AI20: нет | AJ20: нет | AK20: нет | AL20: нет | AM20: 2 | AN20: 57 | AO20: нет | AP20: да | AQ20: беременность | AR20: — | AS20: — | AT20: противопоказан | AU20: нет | AV20: 2 | AW20: умеренная | AX20: умеренная | AY20: GAD-7 | AZ20: не оценивается (< 4 нед. терапии) | BA20: желательно | BB20: беременность
A21: P020 | B21: gtr_contra | C21: Ж | D21: 22 | E21: не работает | F21: Генерализованное тревожное расстройство | G21: F41.1 | H21: 9 | K21: 9 | L21: 0 | M21: 12 | P21: 12 | Q21: 14 | R21: 18 | S21: 18 | T21: да | U21: нет | V21: нет | W21: фолиевая кислота 400 мкг | X21: нет | Y21: нет | Z21: нет | AA21: нет | AB21: нет | AD21: нет | AE21: нет | AF21: нет | AG21: нет | AH21: нет | AI21: нет | AJ21: нет | AK21: нет | AL21: нет | AM21: 0 | AN21: 57 | AO21: безнадёжность | AP21: да | AQ21: беременность | AR21: — | AS21: — | AT21: противопоказан | AU21: нет | AV21: 2 | AW21: лёгкая | AX21: умеренная | AY21: GAD-7 | AZ21: не оценивается (< 4 нед. терапии) | BA21: желательно | BB21: беременность; маркеры безнадёжности в дневнике
A22: P021 | B22: gtr_contra | C22: Ж | D22: 43 | E22: учится | F22: Генерализованное тревожное расстройство | G22: F41.1 | H22: 4 | K22: 4 | L22: 0 | M22: 12 | P22: 12 | Q22: 6 | R22: 18 | S22: 12 | T22: нет | U22: да | V22: нет | X22: нет | Y22: нет | Z22: нет | AA22: нет | AB22: нет | AD22: нет | AE22: нет | AF22: редко | AG22: нет | AH22: нет | AI22: нет | AJ22: нет | AK22: нет | AL22: нет | AM22: 2 | AO22: нет | AP22: да | AQ22: грудное вскармливание | AR22: — | AS22: — | AT22: противопоказан | AU22: нет | AV22: 1 | AW22: минимальная | AX22: умеренная | AY22: GAD-7 | AZ22: не оценивается (< 4 нед. терапии) | BA22: не требуется | BB22: —
A23: P022 | B23: gtr_contra | C23: М | D23: 46 | E23: работает | F23: Генерализованное тревожное расстройство | G23: F41.1 | H23: 8 | K23: 8 | L23: 0 | M23: 16 | P23: 16 | Q23: 12 | R23: 26 | S23: 23 | T23: — | U23: — | V23: — | X23: нет | Y23: нет | Z23: да | AA23: нет | AB23: нет | AD23: нет | AE23: нет | AF23: нет | AG23: нет | AH23: нет | AI23: нет | AJ23: нет | AK23: да | AL23: нет | AM23: 0 | AO23: нет | AP23: да | AQ23: эпилепсия | AR23: вождение — предупредить о головокружении и сонливости | AS23: — | AT23: противопоказан | AU23: нет | AV23: 1 | AW23: лёгкая | AX23: выраженная | AY23: GAD-7 | AZ23: не оценивается (< 4 нед. терапии) | BA23: желательно | BB23: GAD-7 ≥ 15
A24: P023 | B24: gtr_contra | C24: М | D24: 38 | E24: учится | F24: Генерализованное тревожное расстройство | G24: F41.1 | H24: 5 | K24: 5 | L24: 0 | M24: 16 | P24: 16 | Q24: 8 | R24: 26 | S24: 21 | T24: — | U24: — | V24: — | X24: нет | Y24: нет | Z24: нет | AA24: нет | AB24: да | AD24: нет | AE24: нет | AF24: нет | AG24: нет | AH24: нет | AI24: нет | AJ24: нет | AK24: да | AL24: нет | AM24: 0 | AO24: нет | AP24: да | AQ24: печёночная недостаточность (Чайлд-Пью A–C) | AR24: вождение — предупредить о головокружении и сонливости | AS24: — | AT24: противопоказан | AU24: нет | AV24: 1 | AW24: лёгкая | AX24: выраженная | AY24: GAD-7 | AZ24: не оценивается (< 4 нед. терапии) | BA24: желательно | BB24: GAD-7 ≥ 15
A25: P024 | B25: gtr_contra | C25: Ж | D25: 68 | E25: работает | F25: Генерализованное тревожное расстройство | G25: F41.1 | H25: 11 | K25: 11 | L25: 0 | M25: 13 | P25: 13 | Q25: 16 | R25: 20 | S25: 20 | T25: нет | U25: нет | V25: нет | X25: нет | Y25: нет | Z25: нет | AA25: нет | AB25: нет | AC25: 47 | AD25: нет | AE25: нет | AF25: редко | AG25: нет | AH25: нет | AI25: нет | AJ25: нет | AK25: да | AL25: нет | AM25: 0 | AO25: безнадёжность | AP25: да | AQ25: почечная недостаточность, СКФ 47 < 60 мл/мин | AR25: пожилой возраст — выше чувствительность к НЯ; вождение — предупредить о головокружении и сонливости | AS25: — | AT25: противопоказан | AU25: нет | AV25: 1 | AW25: умеренная | AX25: умеренная | AY25: GAD-7 | AZ25: не оценивается (< 4 нед. терапии) | BA25: желательно | BB25: маркеры безнадёжности в дневнике
A26: P025 | B26: gtr_contra | C26: М | D26: 73 | E26: учится и работает | F26: Генерализованное тревожное расстройство | G26: F41.1 | H26: 10 | K26: 10 | L26: 0 | M26: 17 | P26: 17 | Q26: 14 | R26: 26 | S26: 24 | T26: — | U26: — | V26: — | X26: нет | Y26: нет | Z26: нет | AA26: нет | AB26: нет | AC26: 47 | AD26: нет | AE26: нет | AF26: нет | AG26: нет | AH26: нет | AI26: нет | AJ26: нет | AK26: нет | AL26: нет | AM26: 2 | AO26: безнадёжность | AP26: да | AQ26: почечная недостаточность, СКФ 47 < 60 мл/мин | AR26: пожилой возраст — выше чувствительность к НЯ | AS26: — | AT26: противопоказан | AU26: нет | AV26: 1 | AW26: умеренная | AX26: выраженная | AY26: GAD-7 | AZ26: не оценивается (< 4 нед. терапии) | BA26: желательно | BB26: GAD-7 ≥ 15; маркеры безнадёжности в дневнике
A27: P026 | B27: gtr_contra | C27: М | D27: 53 | E27: работает | F27: Генерализованное тревожное расстройство | G27: F41.1 | H27: 9 | K27: 9 | L27: 0 | M27: 12 | P27: 12 | Q27: 14 | R27: 18 | S27: 16 | T27: — | U27: — | V27: — | W27: пирлиндол 25 мг 2 р/сут | X27: да | Y27: нет | Z27: нет | AA27: нет | AB27: нет | AD27: нет | AE27: нет | AF27: редко | AG27: нет | AH27: нет | AI27: нет | AJ27: нет | AK27: да | AL27: нет | AM27: 0 | AN27: 86 | AO27: нет | AP27: да | AQ27: приём ингибитора МАО сейчас или в последние 2 недели | AR27: вождение — предупредить о головокружении и сонливости | AS27: пирлиндол — противопоказано (ингибитор МАО) | AT27: противопоказан | AU27: нет | AV27: 2 | AW27: лёгкая | AX27: умеренная | AY27: GAD-7 | AZ27: не оценивается (< 4 нед. терапии) | BA27: не требуется | BB27: —
A28: P027 | B28: gtr_contra | C28: Ж | D28: 17 | E28: учится | F28: Генерализованное тревожное расстройство | G28: F41.1 | H28: 5 | K28: 5 | L28: 0 | M28: 15 | P28: 15 | Q28: 8 | R28: 24 | S28: 16 | T28: нет | U28: нет | V28: нет | X28: нет | Y28: нет | Z28: нет | AA28: нет | AB28: нет | AD28: нет | AE28: нет | AF28: нет | AG28: нет | AH28: нет | AI28: нет | AJ28: нет | AK28: нет | AL28: нет | AM28: 2 | AO28: нет | AP28: да | AQ28: возраст до 18 лет | AR28: — | AS28: — | AT28: противопоказан | AU28: нет | AV28: 1 | AW28: лёгкая | AX28: выраженная | AY28: GAD-7 | AZ28: не оценивается (< 4 нед. терапии) | BA28: желательно | BB28: GAD-7 ≥ 15
A29: P028 | B29: gtr_contra | C29: Ж | D29: 23 | E29: работает | F29: Генерализованное тревожное расстройство | G29: F41.1 | H29: 4 | K29: 4 | L29: 0 | M29: 16 | P29: 16 | Q29: 6 | R29: 26 | S29: 18 | T29: нет | U29: нет | V29: нет | X29: нет | Y29: маритупирдин (Авиандр) — сыпь | Z29: нет | AA29: нет | AB29: нет | AD29: нет | AE29: нет | AF29: нет | AG29: нет | AH29: нет | AI29: нет | AJ29: нет | AK29: нет | AL29: нет | AM29: 2 | AO29: нет | AP29: да | AQ29: гиперчувствительность к маритупирдину | AR29: — | AS29: — | AT29: противопоказан | AU29: нет | AV29: 1 | AW29: минимальная | AX29: выраженная | AY29: GAD-7 | AZ29: не оценивается (< 4 нед. терапии) | BA29: желательно | BB29: GAD-7 ≥ 15
A30: P029 | B30: gtr_inter | C30: Ж | D30: 39 | E30: учится и работает | F30: Генерализованное тревожное расстройство | G30: F41.1 | H30: 9 | I30: 4 | K30: 4 | L30: 0 | M30: 11 | N30: 5 | P30: 5 | Q30: 6 | R30: 8 | S30: 9 | T30: нет | U30: нет | V30: нет | W30: сертралин 50 мг утром | X30: нет | Y30: нет | Z30: нет | AA30: нет | AB30: нет | AD30: нет | AE30: нет | AF30: редко | AG30: нет | AH30: нет | AI30: нет | AJ30: нет | AK30: нет | AL30: нет | AM30: 4 | AN30: 79 | AO30: нет | AP30: да | AQ30: — | AR30: — | AS30: сертралин — с осторожностью (серотонинергический) | AT30: возможен по инструкции, с осторожностью | AU30: нет | AV30: 2 | AW30: минимальная | AX30: лёгкая | AY30: GAD-7 | AZ30: ответ (≥ 50%) | BA30: не требуется | BB30: —
A31: P030 | B31: gtr_inter | C31: Ж | D31: 29 | E31: работает | F31: Генерализованное тревожное расстройство | G31: F41.1 | H31: 8 | I31: 8 | J31: 7 | K31: 7 | L31: 0 | M31: 12 | N31: 12 | O31: 12 | P31: 12 | Q31: 10 | R31: 18 | S31: 14 | T31: нет | U31: нет | V31: нет | W31: феназепам 0,5 мг на ночь; корвалол 30 капель при тревоге | X31: нет | Y31: нет | Z31: нет | AA31: нет | AB31: нет | AD31: нет | AE31: нет | AF31: редко | AG31: нет | AH31: нет | AI31: нет | AJ31: нет | AK31: нет | AL31: да | AM31: 8 | AN31: 71 | AO31: нет | AP31: да | AQ31: — | AR31: — | AS31: феназепам — с осторожностью (седативный); корвалол — избегать (седативный, содержит этанол) | AT31: возможен по инструкции, с осторожностью | AU31: нет | AV31: 3 | AW31: лёгкая | AX31: умеренная | AY31: GAD-7 | AZ31: недостаточный ответ (< 25%) | BA31: желательно | BB31: недостаточный ответ по GAD-7 за ≥ 4 нед.
A32: P031 | B32: gtr_inter | C32: М | D32: 56 | E32: учится и работает | F32: Генерализованное тревожное расстройство | G32: F41.1 | H32: 9 | I32: 3 | K32: 3 | L32: 0 | M32: 17 | N32: 7 | P32: 7 | Q32: 4 | R32: 10 | S32: 9 | T32: — | U32: — | V32: — | W32: суматриптан 50 мг при приступе | X32: нет | Y32: нет | Z32: нет | AA32: нет | AB32: нет | AD32: нет | AE32: нет | AF32: редко | AG32: нет | AH32: нет | AI32: нет | AJ32: нет | AK32: нет | AL32: нет | AM32: 6 | AN32: 57 | AO32: безнадёжность | AP32: да | AQ32: — | AR32: — | AS32: суматриптан — с осторожностью (серотонинергический) | AT32: возможен по инструкции, с осторожностью | AU32: нет | AV32: 2 | AW32: минимальная | AX32: лёгкая | AY32: GAD-7 | AZ32: ответ (≥ 50%) | BA32: желательно | BB32: маркеры безнадёжности в дневнике
A33: P032 | B33: gtr_inter | C33: М | D33: 31 | E33: учится | F33: Генерализованное тревожное расстройство | G33: F41.1 | H33: 9 | I33: 8 | J33: 6 | K33: 6 | L33: 0 | M33: 19 | N33: 15 | O33: 11 | P33: 11 | Q33: 8 | R33: 18 | S33: 15 | T33: — | U33: — | V33: — | W33: трамадол 50 мг при болях; ибупрофен 400 мг при болях | X33: нет | Y33: нет | Z33: нет | AA33: нет | AB33: нет | AD33: нет | AE33: нет | AF33: редко | AG33: нет | AH33: нет | AI33: нет | AJ33: нет | AK33: нет | AL33: нет | AM33: 8 | AN33: 93 | AO33: безнадёжность | AP33: да | AQ33: — | AR33: — | AS33: трамадол — с осторожностью (серотонинергический) | AT33: возможен по инструкции, с осторожностью | AU33: нет | AV33: 3 | AW33: лёгкая | AX33: умеренная | AY33: GAD-7 | AZ33: частичный ответ (25–49%) | BA33: желательно | BB33: маркеры безнадёжности в дневнике
A34: P033 | B34: gtr_inter | C34: Ж | D34: 21 | E34: учится и работает | F34: Генерализованное тревожное расстройство | G34: F41.1 | H34: 11 | I34: 7 | J34: 4 | K34: 4 | L34: 0 | M34: 16 | N34: 11 | O34: 6 | P34: 6 | Q34: 6 | R34: 10 | S34: 8 | T34: нет | U34: нет | V34: нет | W34: тербинафин 250 мг | X34: нет | Y34: нет | Z34: нет | AA34: нет | AB34: нет | AD34: нет | AE34: нет | AF34: нет | AG34: нет | AH34: нет | AI34: нет | AJ34: нет | AK34: нет | AL34: да | AM34: 8 | AN34: 93 | AO34: нет | AP34: да | AQ34: — | AR34: — | AS34: тербинафин — с осторожностью (ингибитор CYP2D6) | AT34: возможен по инструкции, с осторожностью | AU34: нет | AV34: 2 | AW34: минимальная | AX34: лёгкая | AY34: GAD-7 | AZ34: ответ (≥ 50%) | BA34: не требуется | BB34: —
A35: P034 | B35: gtr_inter | C35: М | D35: 44 | E35: учится и работает | F35: Генерализованное тревожное расстройство | G35: F41.1 | H35: 8 | I35: 5 | J35: 3 | K35: 3 | L35: 0 | M35: 19 | N35: 12 | O35: 6 | P35: 6 | Q35: 4 | R35: 10 | S35: 9 | T35: — | U35: — | V35: — | W35: доксиламин 15 мг на ночь; хлоропирамин 25 мг при аллергии | X35: нет | Y35: нет | Z35: нет | AA35: нет | AB35: нет | AD35: нет | AE35: нет | AF35: редко | AG35: нет | AH35: нет | AI35: нет | AJ35: нет | AK35: нет | AL35: нет | AM35: 8 | AN35: 57 | AO35: нет | AP35: да | AQ35: — | AR35: — | AS35: доксиламин — с осторожностью (седативный); хлоропирамин — с осторожностью (седативный) | AT35: возможен по инструкции, с осторожностью | AU35: нет | AV35: 3 | AW35: минимальная | AX35: лёгкая | AY35: GAD-7 | AZ35: ответ (≥ 50%) | BA35: не требуется | BB35: —
A36: P035 | B36: gtr_inter | C36: Ж | D36: 54 | E36: учится и работает | F36: Генерализованное тревожное расстройство | G36: F41.1 | H36: 5 | I36: 2 | K36: 2 | L36: 0 | M36: 13 | N36: 4 | P36: 4 | Q36: 2 | R36: 6 | S36: 8 | T36: нет | U36: нет | V36: нет | W36: пароксетин 20 мг утром; зопиклон 7,5 мг на ночь | X36: нет | Y36: нет | Z36: нет | AA36: нет | AB36: нет | AD36: нет | AE36: нет | AF36: редко | AG36: нет | AH36: нет | AI36: нет | AJ36: нет | AK36: нет | AL36: да | AM36: 4 | AN36: 71 | AO36: безнадёжность | AP36: да | AQ36: — | AR36: — | AS36: пароксетин — с осторожностью (серотонинергический, ингибитор CYP2D6); зопиклон — с осторожностью (седативный) | AT36: возможен по инструкции, с осторожностью | AU36: нет | AV36: 3 | AW36: минимальная | AX36: минимальная | AY36: GAD-7 | AZ36: ответ (≥ 50%) | BA36: желательно | BB36: маркеры безнадёжности в дневнике
A37: P036 | B37: covid | C37: М | D37: 55 | E37: учится | F37: Расстройство адаптации с тревогой; состояние после COVID-19 | G37: F43.2; U09.9 | H37: 9 | I37: 8 | J37: 8 | K37: 8 | L37: 0 | M37: 14 | N37: 15 | O37: 15 | P37: 15 | Q37: 12 | R37: 24 | S37: 20 | T37: — | U37: — | V37: — | W37: омепразол 20 мг | X37: нет | Y37: нет | Z37: нет | AA37: нет | AB37: нет | AD37: нет | AE37: нет | AF37: редко | AG37: нет | AH37: нет | AI37: нет | AJ37: нет | AK37: нет | AL37: нет | AM37: 8 | AN37: 86 | AO37: нет | AP37: да | AQ37: — | AR37: — | AS37: — | AT37: возможен по инструкции | AU37: нет | AV37: 2 | AW37: лёгкая | AX37: выраженная | AY37: GAD-7 | AZ37: недостаточный ответ (< 25%) | BA37: желательно | BB37: GAD-7 ≥ 15; недостаточный ответ по GAD-7 за ≥ 4 нед.
A38: P037 | B38: covid | C38: Ж | D38: 47 | E38: работает | F38: Расстройство адаптации с тревогой; состояние после COVID-19 | G38: F43.2; U09.9 | H38: 4 | I38: 3 | J38: 2 | K38: 2 | L38: 0 | M38: 11 | N38: 8 | O38: 4 | P38: 4 | Q38: 2 | R38: 6 | S38: 6 | T38: нет | U38: нет | V38: нет | W38: омепразол 20 мг | X38: нет | Y38: нет | Z38: нет | AA38: нет | AB38: нет | AD38: нет | AE38: нет | AF38: редко | AG38: нет | AH38: нет | AI38: нет | AJ38: нет | AK38: нет | AL38: нет | AM38: 8 | AN38: 71 | AO38: нет | AP38: да | AQ38: — | AR38: — | AS38: — | AT38: возможен по инструкции | AU38: нет | AV38: 2 | AW38: минимальная | AX38: минимальная | AY38: GAD-7 | AZ38: ответ (≥ 50%) | BA38: не требуется | BB38: —
A39: P038 | B39: covid | C39: М | D39: 53 | E39: учится | F39: Расстройство адаптации с тревогой; состояние после COVID-19 | G39: F43.2; U09.9 | H39: 6 | I39: 6 | K39: 6 | L39: 0 | M39: 15 | N39: 12 | P39: 12 | Q39: 8 | R39: 18 | S39: 17 | T39: — | U39: — | V39: — | W39: доксиламин 15 мг на ночь | X39: нет | Y39: нет | Z39: нет | AA39: нет | AB39: нет | AD39: нет | AE39: нет | AF39: редко | AG39: нет | AH39: нет | AI39: нет | AJ39: нет | AK39: нет | AL39: да | AM39: 4 | AN39: 93 | AO39: нет | AP39: да | AQ39: — | AR39: — | AS39: доксиламин — с осторожностью (седативный) | AT39: возможен по инструкции, с осторожностью | AU39: нет | AV39: 2 | AW39: лёгкая | AX39: умеренная | AY39: GAD-7 | AZ39: недостаточный ответ (< 25%) | BA39: желательно | BB39: недостаточный ответ по GAD-7 за ≥ 4 нед.
A40: P039 | B40: covid | C40: Ж | D40: 35 | E40: работает | F40: Расстройство адаптации с тревогой; состояние после COVID-19 | G40: F43.2; U09.9 | H40: 9 | I40: 6 | J40: 3 | K40: 3 | L40: 0 | M40: 15 | N40: 11 | O40: 7 | P40: 7 | Q40: 4 | R40: 10 | S40: 9 | T40: нет | U40: нет | V40: нет | W40: омепразол 20 мг | X40: нет | Y40: нет | Z40: нет | AA40: нет | AB40: нет | AD40: нет | AE40: нет | AF40: редко | AG40: нет | AH40: нет | AI40: нет | AJ40: нет | AK40: да | AL40: да | AM40: 8 | AN40: 71 | AO40: нет | AP40: да | AQ40: — | AR40: вождение — предупредить о головокружении и сонливости | AS40: — | AT40: возможен по инструкции, с осторожностью | AU40: нет | AV40: 2 | AW40: минимальная | AX40: лёгкая | AY40: GAD-7 | AZ40: ответ (≥ 50%) | BA40: не требуется | BB40: —
...

Sheet Дневник
A1: entry_id | B1: patient_id | C1: date | D1: mood_1_5 | E1: format | F1: smer_situation | G1: smer_thoughts | H1: smer_emotions | I1: smer_intensity_0_100 | J1: smer_reaction | K1: free_text | L1: full_text | M1: risk_label | N1: trap_type | O1: difficulty | P1: rationale
A2: D0001 | B2: P001 | C2: 2026-09-02 | D2: 3 | E2: СМЭР | F2: Сломался ноутбук перед дедлайном | G2: Готовлю доклад по суицидологии для университета | H2: грусть | I2: 70 | J2: Промолчала, хотя хотелось ответить | L2: Сломался ноутбук перед дедлайном. Готовлю доклад по суицидологии для университета. Промолчала, хотя хотелось ответить. | M2: нет | N2: media | O2: трудный | P2: Фильм/статья/учёба, не о себе
A3: D0002 | B3: P001 | C3: 2026-09-02 | D3: 2 | E3: СМЭР | F3: Начальник написал «зайди ко мне» | G3: Меня никто не слушает | H3: раздражение | I3: 60 | J3: Лежала на диване, ничего не делала | L3: Начальник написал «зайди ко мне» Меня никто не слушает. Лежала на диване, ничего не делала. | M3: нет | N3: нет | O3: лёгкий | P3: Обычные переживания без признаков риска
A4: D0003 | B4: P001 | C4: 2026-09-16 | D4: 4 | E4: СМЭР | F4: Сходили с подругой в кафе | G4: Хорошо, что я всё-таки пошла | H4: спокойствие | I4: 60 | J4: Захотелось позвонить друзьям | L4: Сходили с подругой в кафе. Хорошо, что я всё-таки пошла. Захотелось позвонить друзьям. | M4: нет | N4: нет | O4: лёгкий | P4: Обычные переживания без признаков риска
A5: D0004 | B5: P001 | C5: 2026-09-29 | D5: 3 | E5: СМЭР | F5: Позвали на день рождения | G5: Я устала от этой недели | H5: бессилие | I5: 30 | J5: Извинялась весь вечер | L5: Позвали на день рождения. Я устала от этой недели. Извинялась весь вечер. | M5: нет | N5: нет | O5: лёгкий | P5: Обычные переживания без признаков риска
A6: D0005 | B6: P001 | C6: 2026-10-01 | D6: 4 | E6: свободно | K6: Сломался ноутбук перед дедлайном. Соседка жаловалась, что ей незачем жить, посоветовала ей сходить к врачу. | L6: Сломался ноутбук перед дедлайном. Соседка жаловалась, что ей незачем жить, посоветовала ей сходить к врачу. | M6: нет | N6: third_party | O6: трудный | P6: Речь о другом человеке, не о себе (клинически значимо для близкого, но не риск пациента)
A7: D0006 | B7: P001 | C7: 2026-10-13 | D7: 5 | E7: СМЭР | F7: Купила билеты в отпуск | G7: Хорошо, что я всё-таки пошла | H7: облегчение | I7: 60 | J7: Захотелось позвонить друзьям | L7: Купила билеты в отпуск. Хорошо, что я всё-таки пошла. Захотелось позвонить друзьям. | M7: нет | N7: нет | O7: лёгкий | P7: Обычные переживания без признаков риска
A8: D0007 | B8: P001 | C8: 2026-10-15 | D8: 4 | E8: СМЭР | F8: Сходили с подругой в кафе | G8: Хорошо, что я всё-таки пошла | H8: радость, облегчение | I8: 30 | J8: Запланировала ещё одну встречу | L8: Сходили с подругой в кафе. Хорошо, что я всё-таки пошла. Запланировала ещё одну встречу. | M8: нет | N8: нет | O8: лёгкий | P8: Обычные переживания без признаков риска
A9: D0008 | B9: P001 | C9: 2026-10-23 | D9: 2 | E9: свободно | K9: Живу на автопилоте, внутри ноль. Не спала до утра. | L9: Живу на автопилоте, внутри ноль. Не спала до утра. | M9: безнадёжность | N9: indirect | O9: трудный | P9: Безнадёжность/никчёмность/обременённость без упоминания смерти (косвенно)
A10: D0009 | B10: P002 | C10: 2026-08-29 | D10: 2 | E10: СМЭР | F10: Подруга не ответила на сообщение | G10: Не успею, и всё сорвётся | H10: тревога, стыд | I10: 40 | J10: Отказался от встречи | L10: Подруга не ответила на сообщение. Не успею, и всё сорвётся. Отказался от встречи. | M10: нет | N10: нет | O10: лёгкий | P10: Обычные переживания без признаков риска
A11: D0010 | B11: P002 | C11: 2026-09-08 | D11: 5 | E11: свободно | K11: Купил билеты в отпуск. Было спокойно и тепло. | L11: Купил билеты в отпуск. Было спокойно и тепло. | M11: нет | N11: нет | O11: лёгкий | P11: Обычные переживания без признаков риска
A12: D0011 | B12: P002 | C12: 2026-09-09 | D12: 5 | E12: СМЭР | F12: Позвали на день рождения | G12: Чуть не умер со смеху от видео | H12: радость | I12: 60 | J12: Позвонил маме | L12: Позвали на день рождения. Чуть не умер со смеху от видео. Позвонил маме. | M12: нет | N12: idiom | O12: трудный | P12: Устойчивое выражение/гипербола, нет личного намерения
A13: D0012 | B13: P002 | C13: 2026-09-13 | D13: 1 | E13: СМЭР | F13: Позвали на день рождения | G13: Ничего уже не изменится | H13: грусть, бессилие | I13: 60 | J13: Весь вечер прокручивал это в голове | L13: Позвали на день рождения. Ничего уже не изменится. Весь вечер прокручивал это в голове. | M13: безнадёжность | N13: нет | O13: лёгкий | P13: Безнадёжность/никчёмность/обременённость без упоминания смерти
A14: D0013 | B14: P002 | C14: 2026-09-29 | D14: 4 | E14: свободно | K14: Было приятно, что меня поддержали. Захотелось позвонить друзьям. | L14: Было приятно, что меня поддержали. Захотелось позвонить друзьям. | M14: нет | N14: нет | O14: лёгкий | P14: Обычные переживания без признаков риска
A15: D0014 | B15: P002 | C15: 2026-10-08 | D15: 2 | E15: СМЭР | F15: Коллега рассказала, что её отец покончил с собой много лет назад | G15: Не успею, и всё сорвётся | H15: страх | I15: 50 | J15: Лёг спать раньше | L15: Коллега рассказала, что её отец покончил с собой много лет назад. Не успею, и всё сорвётся. Лёг спать раньше. | M15: нет | N15: third_party | O15: трудный | P15: Речь о другом человеке, не о себе (клинически значимо для близкого, но не риск пациента)
A16: D0015 | B16: P003 | C16: 2026-09-12 | D16: 4 | E16: СМЭР | F16: Погуляла в парке 40 минут | G16: Получилось лучше, чем я думала | H16: радость | I16: 40 | J16: Улыбалась весь вечер | L16: Погуляла в парке 40 минут. Получилось лучше, чем я думала. Улыбалась весь вечер. | M16: нет | N16: нет | O16: лёгкий | P16: Обычные переживания без признаков риска
A17: D0016 | B17: P003 | C17: 2026-09-15 | D17: 5 | E17: СМЭР | F17: Погуляла в парке 40 минут | G17: Хорошо, что я всё-таки пошла | H17: радость | I17: 20 | J17: Улыбалась весь вечер | L17: Погуляла в парке 40 минут. Хорошо, что я всё-таки пошла. Улыбалась весь вечер. | M17: нет | N17: нет | O17: лёгкий | P17: Обычные переживания без признаков риска
A18: D0017 | B18: P003 | C18: 2026-09-19 | D18: 3 | E18: свободно | K18: Грустно, что так вышло. Промолчала, хотя хотелось ответить. | L18: Грустно, что так вышло. Промолчала, хотя хотелось ответить. | M18: нет | N18: нет | O18: лёгкий | P18: Обычные переживания без признаков риска
A19: D0018 | B19: P003 | C19: 2026-09-22 | D19: 2 | E19: свободно | K19: Жду результаты анализов. Сейчас начнётся паника. | L19: Жду результаты анализов. Сейчас начнётся паника. | M19: нет | N19: нет | O19: лёгкий | P19: Обычные переживания без признаков риска
A20: D0019 | B20: P003 | C20: 2026-09-25 | D20: 3 | E20: свободно | K20: Сколько можно. Сделала пару вдохов и продолжила работу. | L20: Сколько можно. Сделала пару вдохов и продолжила работу. | M20: нет | N20: нет | O20: лёгкий | P20: Обычные переживания без признаков риска
A21: D0020 | B21: P003 | C21: 2026-10-17 | D21: 3 | E21: СМЭР | F21: Поссорились с партнёром из-за мелочи | G21: Скучаю по старым временам | H21: грусть, бессилие | I21: 40 | J21: Сделала технику дыхания из приложения | L21: Поссорились с партнёром из-за мелочи. Скучаю по старым временам. Сделала технику дыхания из приложения. | M21: нет | N21: нет | O21: лёгкий | P21: Обычные переживания без признаков риска
A22: D0021 | B22: P003 | C22: 2026-10-24 | D22: 4 | E22: свободно | K22: Начальник написал «зайди ко мне» Не хочу ничего с собой делать, хочу жить нормально. | L22: Начальник написал «зайди ко мне» Не хочу ничего с собой делать, хочу жить нормально. | M22: нет | N22: negation | O22: трудный | P22: Отрицание мыслей о смерти/самоповреждении или нерисковое утверждение
A23: D0022 | B23: P004 | C23: 2026-09-07 | D23: 2 | E23: СМЭР | F23: Соседи шумели всю ночь | G23: Хочется просто полежать | H23: бессилие | I23: 70 | J23: Сердце колотилось, вспотели ладони | L23: Соседи шумели всю ночь. Хочется просто полежать. Сердце колотилось, вспотели ладони. | M23: нет | N23: нет | O23: лёгкий | P23: Обычные переживания без признаков риска
A24: D0023 | B24: P004 | C24: 2026-09-12 | D24: 4 | E24: свободно | K24: Я убита новостью — сериал закрыли. Сделала технику дыхания из приложения. | L24: Я убита новостью — сериал закрыли. Сделала технику дыхания из приложения. | M24: нет | N24: idiom | O24: трудный | P24: Устойчивое выражение/гипербола, нет личного намерения
A25: D0024 | B25: P004 | C25: 2026-09-21 | D25: 3 | E25: СМЭР | F25: Совещание перенесли на вечер | G25: Вечером одиноко | H25: грусть, обида | I25: 50 | J25: Извинялась весь вечер | L25: Совещание перенесли на вечер. Вечером одиноко. Извинялась весь вечер. | M25: нет | N25: нет | O25: лёгкий | P25: Обычные переживания без признаков риска
A26: D0025 | B26: P004 | C26: 2026-10-10 | D26: 3 | E26: свободно | K26: Пропустила утреннюю таблетку. Если не отвечают, значит, что-то случилось. | L26: Пропустила утреннюю таблетку. Если не отвечают, значит, что-то случилось. | M26: нет | N26: нет | O26: лёгкий | P26: Обычные переживания без признаков риска
A27: D0026 | B27: P004 | C27: 2026-10-17 | D27: 4 | E27: СМЭР | F27: Утром начальник попросил переделать отчёт | G27: Я самая несчастная человек на свете: кончился кофе | H27: бессилие | I27: 20 | J27: Сердце колотилось, вспотели ладони | L27: Утром начальник попросил переделать отчёт. Я самая несчастная человек на свете: кончился кофе. Сердце колотилось, вспотели ладони. | M27: нет | N27: sarcasm | O27: трудный | P27: Ирония/гипербола по бытовому поводу
A28: D0027 | B28: P005 | C28: 2026-08-31 | D28: 5 | E28: СМЭР | F28: Приготовила ужин для семьи | G28: Хорошо, что я всё-таки пошла | H28: радость, облегчение | I28: 30 | J28: Захотелось позвонить друзьям | L28: Приготовила ужин для семьи. Хорошо, что я всё-таки пошла. Захотелось позвонить друзьям. | M28: нет | N28: нет | O28: лёгкий | P28: Обычные переживания без признаков риска
A29: D0028 | B29: P005 | C29: 2026-09-14 | D29: 2 | E29: СМЭР | F29: Вечер дома одна | G29: У меня точно что-то серьёзное со здоровьем | H29: тревога, страх | I29: 20 | J29: Легла спать раньше | L29: Вечер дома одна. У меня точно что-то серьёзное со здоровьем. Легла спать раньше. | M29: нет | N29: нет | O29: лёгкий | P29: Обычные переживания без признаков риска
A30: D0029 | B30: P005 | C30: 2026-10-06 | D30: 3 | E30: свободно | K30: Позвали на день рождения. Опять я всё испортила. | L30: Позвали на день рождения. Опять я всё испортила. | M30: нет | N30: нет | O30: лёгкий | P30: Обычные переживания без признаков риска
A31: D0030 | B31: P005 | C31: 2026-10-15 | D31: 1 | E31: СМЭР | F31: Первый день на новой работе | G31: Зачем вообще стараться | H31: грусть, бессилие | I31: 70 | J31: Сердце колотилось, вспотели ладони | L31: Первый день на новой работе. Зачем вообще стараться. Сердце колотилось, вспотели ладони. | M31: безнадёжность | N31: нет | O31: лёгкий | P31: Безнадёжность/никчёмность/обременённость без упоминания смерти
A32: D0031 | B32: P006 | C32: 2026-09-07 | D32: 2 | E32: СМЭР | F32: Отправила резюме и жду ответа | G32: Хочется просто полежать | H32: грусть, обида | I32: 30 | J32: Сделала пару вдохов и продолжила работу | L32: Отправила резюме и жду ответа. Хочется просто полежать. Сделала пару вдохов и продолжила работу. | M32: нет | N32: нет | O32: лёгкий | P32: Обычные переживания без признаков риска
A33: D0032 | B33: P006 | C33: 2026-09-28 | D33: 2 | E33: СМЭР | F33: Жду результаты анализов | G33: Почему опять я? | H33: злость, обида | I33: 20 | J33: Сделала пару вдохов и продолжила работу | L33: Жду результаты анализов. Почему опять я? Сделала пару вдохов и продолжила работу. | M33: нет | N33: нет | O33: лёгкий | P33: Обычные переживания без признаков риска
A34: D0033 | B34: P006 | C34: 2026-10-22 | D34: 2 | E34: СМЭР | F34: Друзья обсуждали поездку без меня | G34: Меня никто не слушает | H34: раздражение | I34: 70 | J34: Съела что-то сладкое | L34: Друзья обсуждали поездку без меня. Меня никто не слушает. Съела что-то сладкое. | M34: нет | N34: нет | O34: лёгкий | P34: Обычные переживания без признаков риска
A35: D0034 | B35: P007 | C35: 2026-09-05 | D35: 3 | E35: СМЭР | F35: Сломался ноутбук перед дедлайном | G35: Исчезнуть бы на выходные в лес и отдохнуть от всех | H35: тревога | I35: 60 | J35: Отложил задачу до вечера | L35: Сломался ноутбук перед дедлайном. Исчезнуть бы на выходные в лес и отдохнуть от всех. Отложил задачу до вечера. | M35: нет | N35: sarcasm | O35: трудный | P35: Ирония/гипербола по бытовому поводу
A36: D0035 | B36: P007 | C36: 2026-09-21 | D36: 5 | E36: свободно | K36: Съездили за город на выходные. Было приятно, что меня поддержали. | L36: Съездили за город на выходные. Было приятно, что меня поддержали. | M36: нет | N36: нет | O36: лёгкий | P36: Обычные переживания без признаков риска
A37: D0036 | B37: P007 | C37: 2026-09-23 | D37: 2 | E37: свободно | K37: Если не отвечают, значит, что-то случилось. Промолчал, хотя хотелось ответить. | L37: Если не отвечают, значит, что-то случилось. Промолчал, хотя хотелось ответить. | M37: нет | N37: нет | O37: лёгкий | P37: Обычные переживания без признаков риска
A38: D0037 | B38: P007 | C38: 2026-09-29 | D38: 3 | E38: СМЭР | F38: Первый день на новой работе | G38: Сегодня всё как-то серо | H38: грусть, бессилие | I38: 70 | J38: Сходил в душ и немного успокоился | L38: Первый день на новой работе. Сегодня всё как-то серо. Сходил в душ и немного успокоился. | M38: нет | N38: нет | O38: лёгкий | P38: Обычные переживания без признаков риска
A39: D0038 | B39: P007 | C39: 2026-10-04 | D39: 1 | E39: СМЭР | F39: Поссорились с партнёром из-за мелочи | G39: Мне никогда не станет лучше | H39: вина | I39: 90 | J39: Не спал до утра | L39: Поссорились с партнёром из-за мелочи. Мне никогда не станет лучше. Не спал до утра. | M39: безнадёжность | N39: нет | O39: лёгкий | P39: Безнадёжность/никчёмность/обременённость без упоминания смерти
A40: D0039 | B40: P007 | C40: 2026-10-08 | D40: 5 | E40: СМЭР | F40: Похвалили на работе за проект | G40: Хочется повторить | H40: радость, облегчение | I40: 60 | J40: Спокойно уснул | L40: Похвалили на работе за проект. Хочется повторить. Спокойно уснул. | M40: нет | N40: нет | O40: лёгкий | P40: Обычные переживания без признаков риска
...

Sheet Выписки
A1: note_id | B1: patient_id | C1: style | D1: text | E1: gt_age | F1: gt_sex | G1: gt_diagnosis_main | H1: gt_icd10_main | I1: gt_icd10_all | J1: gt_meds_inn | K1: gt_meds_as_written | L1: gt_allergy | M1: gt_pregnancy | N1: gt_lactation | O1: gt_gfr | P1: gt_creatinine | Q1: gt_epilepsy | R1: gt_liver_failure | S1: gt_alcohol
A2: N001 | B2: P001 | C2: структурированная выписка | D2: ВЫПИСКА ИЗ АМБУЛАТОРНОЙ КАРТЫ Пациентка З., 45 лет, пол: жен. Жалобы: постоянное беспокойство, напряжение, нарушения сна. Диагноз основной: F41.1 Генерализованное тревожное расстройство. Сопутствующие заболевания: нет. Принимает: Мелатонин 3 мг на ночь. Аллергоанамнез не отягощён. Беременность отрицает. Алкоголь: не употребляет. Эпилепсию, ЧМТ отрицает. | E2: 45 | F2: Ж | G2: Генерализованное тревожное расстройство | H2: F41.1 | I2: F41.1 | J2: мелатонин | K2: мелатонин | L2: нет | M2: нет | N2: нет | O2: не указано | P2: не указано | Q2: нет | R2: не указано | S2: нет
A3: N002 | B3: P003 | C3: свободный текст | D3: Пациентка Т. 50 лет обратилась с жалобами на тревогу и напряжение, которые сохраняются несколько месяцев. Хронические заболевания отрицает. Лекарств не принимает. Аллергических реакций не отмечает. Беременность отрицает. Алкоголь — эпизодически. Заключение: Генерализованное тревожное расстройство (F41.1). | E3: 50 | F3: Ж | G3: Генерализованное тревожное расстройство | H3: F41.1 | I3: F41.1 | J3: — | K3: — | L3: нет | M3: нет | N3: нет | O3: не указано | P3: не указано | Q3: не указано | R3: не указано | S3: редко
A4: N003 | B4: P004 | C4: сокращения | D4: Пациентка Н, 31 л., ж. Д-з: F41.1 — Генерализованное тревожное расстройство. Сопут.: —. Терапия: Нурофен 400 мг при болях. Аллергия: отрицает. Б-ть: нет. Алк.: эпизодически. | E4: 31 | F4: Ж | G4: Генерализованное тревожное расстройство | H4: F41.1 | I4: F41.1 | J4: ибупрофен | K4: Нурофен | L4: нет | M4: нет | N4: нет | O4: не указано | P4: не указано | Q4: не указано | R4: не указано | S4: редко
A5: N004 | B5: P005 | C5: выписной эпикриз | D5: ВЫПИСНОЙ ЭПИКРИЗ Пациентка А., возраст 53. Находилась на лечении в дневном стационаре. Клинический диагноз: основной — Генерализованное тревожное расстройство (F41.1). Лекарственная терапия на момент выписки: Мелатонин 3 мг на ночь. Аллергологический анамнез: без особенностей. Лабораторно: без клинически значимых отклонений. Беременность: нет. Вредные привычки: алкоголь эпизодически. | E5: 53 | F5: Ж | G5: Генерализованное тревожное расстройство | H5: F41.1 | I5: F41.1 | J5: мелатонин | K5: мелатонин | L5: нет | M5: нет | N5: нет | O5: не указано | P5: не указано | Q5: не указано | R5: не указано | S5: редко
A6: N005 | B6: P012 | C6: направление | D6: НАПРАВЛЕНИЕ НА КОНСУЛЬТАЦИЮ Пациентка С., 28 лет. Предварительный диагноз: Генерализованное тревожное расстройство, F41.1. Обоснование: тревога, GAD-7 4 баллов (минимальная). Сопутствующие: Сахарный диабет 2 типа (E11.9). Принимает: Эутирокс 50 мкг утром. Беременность — нет. Аллергия — нет. Эпилепсия — нет. | E6: 28 | F6: Ж | G6: Генерализованное тревожное расстройство | H6: F41.1 | I6: F41.1; E11.9 | J6: левотироксин | K6: Эутирокс | L6: нет | M6: нет | N6: нет | O6: не указано | P6: не указано | Q6: нет | R6: не указано | S6: редко
A7: N006 | B7: P013 | C7: структурированная выписка | D7: ВЫПИСКА ИЗ АМБУЛАТОРНОЙ КАРТЫ Пациентка Р., 55 лет, пол: жен. Жалобы: постоянное беспокойство, напряжение, нарушения сна. Диагноз основной: F41.1 Генерализованное тревожное расстройство. Сопутствующие заболевания: нет. Постоянно лекарственные препараты не принимает. Аллергоанамнез не отягощён. Беременность отрицает. Алкоголь: регулярно, до 3–4 раз в неделю. Эпилепсию, ЧМТ отрицает. | E7: 55 | F7: Ж | G7: Генерализованное тревожное расстройство | H7: F41.1 | I7: F41.1 | J7: — | K7: — | L7: нет | M7: нет | N7: нет | O7: не указано | P7: не указано | Q7: нет | R7: не указано | S7: часто
A8: N007 | B8: P018 | C8: свободный текст | D8: Пациент А. 57 лет обратился с жалобами на тревогу и напряжение, которые сохраняются несколько месяцев. В анамнезе гипертоническая болезнь ii ст. (i11.9); сахарный диабет 2 типа (e11.9). Получает конкор 5 мг; аторвастатин 20 мг; метформин 1000 мг 2 р/сут; эналаприл 10 мг. Аллергических реакций не отмечает. Алкоголь — не употребляет. Заключение: Генерализованное тревожное расстройство (F41.1). | E8: 57 | F8: М | G8: Генерализованное тревожное расстройство | H8: F41.1 | I8: F41.1; I11.9; E11.9 | J8: бисопролол; аторвастатин; метформин; эналаприл | K8: Конкор; аторвастатин; метформин; эналаприл | L8: нет | M8: не применимо | N8: не применимо | O8: не указано | P8: не указано | Q8: не указано | R8: не указано | S8: нет
A9: N008 | B9: P019 | C9: сокращения | D9: Пациентка И, 36 л., ж. Д-з: F41.1 — Генерализованное тревожное расстройство. Сопут.: —. Терапия: Фолиевая кислота 400 мкг. Аллергия: отрицает. Б-ть: да, 12 нед. Алк.: эпизодически. | E9: 36 | F9: Ж | G9: Генерализованное тревожное расстройство | H9: F41.1 | I9: F41.1 | J9: фолиевая кислота | K9: фолиевая кислота | L9: нет | M9: да | N9: нет | O9: не указано | P9: не указано | Q9: не указано | R9: не указано | S9: редко
A10: N009 | B10: P020 | C10: выписной эпикриз | D10: ВЫПИСНОЙ ЭПИКРИЗ Пациентка Я., возраст 22. Находилась на лечении в дневном стационаре. Клинический диагноз: основной — Генерализованное тревожное расстройство (F41.1). Лекарственная терапия на момент выписки: Фолиевая кислота 400 мкг. Аллергологический анамнез: без особенностей. Лабораторно: без клинически значимых отклонений. Беременность: да, 12 нед. Вредные привычки: алкоголь не употребляет. | E10: 22 | F10: Ж | G10: Генерализованное тревожное расстройство | H10: F41.1 | I10: F41.1 | J10: фолиевая кислота | K10: фолиевая кислота | L10: нет | M10: да | N10: нет | O10: не указано | P10: не указано | Q10: не указано | R10: не указано | S10: нет
A11: N010 | B11: P021 | C11: направление | D11: НАПРАВЛЕНИЕ НА КОНСУЛЬТАЦИЮ Пациентка В., 43 лет. Предварительный диагноз: Генерализованное тревожное расстройство, F41.1. Обоснование: тревога, GAD-7 12 баллов (умеренная). Сопутствующие: нет. Принимает: ничего. Беременность — нет. Лактация — да. Аллергия — нет. Эпилепсия — нет. | E11: 43 | F11: Ж | G11: Генерализованное тревожное расстройство | H11: F41.1 | I11: F41.1 | J11: — | K11: — | L11: нет | M11: нет | N11: да | O11: не указано | P11: не указано | Q11: нет | R11: не указано | S11: редко
A12: N011 | B12: P022 | C12: структурированная выписка | D12: ВЫПИСКА ИЗ АМБУЛАТОРНОЙ КАРТЫ Пациент К., 46 лет, пол: муж. Жалобы: постоянное беспокойство, напряжение, нарушения сна. Диагноз основной: F41.1 Генерализованное тревожное расстройство. Сопутствующие заболевания: Эпилепсия, ремиссия (G40.9). Постоянно лекарственные препараты не принимает. Аллергоанамнез не отягощён. Алкоголь: не употребляет. | E12: 46 | F12: М | G12: Генерализованное тревожное расстройство | H12: F41.1 | I12: F41.1; G40.9 | J12: — | K12: — | L12: нет | M12: не применимо | N12: не применимо | O12: не указано | P12: не указано | Q12: да | R12: не указано | S12: нет
A13: N012 | B13: P023 | C13: свободный текст | D13: Пациент Ш. 38 лет обратился с жалобами на тревогу и напряжение, которые сохраняются несколько месяцев. В анамнезе цирроз печени, класс a по чайлд-пью (k74.6). Лекарств не принимает. Аллергических реакций не отмечает. Алкоголь — не употребляет. Заключение: Генерализованное тревожное расстройство (F41.1). | E13: 38 | F13: М | G13: Генерализованное тревожное расстройство | H13: F41.1 | I13: F41.1; K74.6 | J13: — | K13: — | L13: нет | M13: не применимо | N13: не применимо | O13: не указано | P13: не указано | Q13: не указано | R13: да | S13: нет
A14: N013 | B14: P024 | C14: сокращения | D14: Пациентка К, 68 л., ж. Д-з: F41.1 — Генерализованное тревожное расстройство. Сопут.: ХБП 3а (N18.3). Терапия: не получает. Аллергия: отрицает. Б-ть: нет. Алк.: эпизодически. СКФ 47. | E14: 68 | F14: Ж | G14: Генерализованное тревожное расстройство | H14: F41.1 | I14: F41.1; N18.3 | J14: — | K14: — | L14: нет | M14: нет | N14: нет | O14: 47 | P14: 158 | Q14: не указано | R14: не указано | S14: редко
A15: N014 | B15: P025 | C15: выписной эпикриз | D15: ВЫПИСНОЙ ЭПИКРИЗ Пациент Е., возраст 73. Находился на лечении в дневном стационаре. Клинический диагноз: основной — Генерализованное тревожное расстройство (F41.1); сопутствующие — ХБП 3а (N18.3). Лекарственная терапия на момент выписки: не назначалась. Аллергологический анамнез: без особенностей. Лабораторно: креатинин 158 мкмоль/л, СКФ 47 мл/мин/1,73 м². Вредные привычки: алкоголь не употребляет. | E15: 73 | F15: М | G15: Генерализованное тревожное расстройство | H15: F41.1 | I15: F41.1; N18.3 | J15: — | K15: — | L15: нет | M15: не применимо | N15: не применимо | O15: 47 | P15: 158 | Q15: не указано | R15: не указано | S15: нет
A16: N015 | B16: P026 | C16: направление | D16: НАПРАВЛЕНИЕ НА КОНСУЛЬТАЦИЮ Пациент П., 53 лет. Предварительный диагноз: Генерализованное тревожное расстройство, F41.1. Обоснование: тревога, GAD-7 12 баллов (умеренная). Сопутствующие: нет. Принимает: Пиразидол 25 мг 2 р/сут. Аллергия — нет. Эпилепсия — нет. | E16: 53 | F16: М | G16: Генерализованное тревожное расстройство | H16: F41.1 | I16: F41.1 | J16: пирлиндол | K16: Пиразидол | L16: нет | M16: не применимо | N16: не применимо | O16: не указано | P16: не указано | Q16: нет | R16: не указано | S16: редко
A17: N016 | B17: P027 | C17: структурированная выписка | D17: ВЫПИСКА ИЗ АМБУЛАТОРНОЙ КАРТЫ Пациентка З., 17 лет, пол: жен. Жалобы: постоянное беспокойство, напряжение, нарушения сна. Диагноз основной: F41.1 Генерализованное тревожное расстройство. Сопутствующие заболевания: нет. Постоянно лекарственные препараты не принимает. Аллергоанамнез не отягощён. Беременность отрицает. Алкоголь: не употребляет. Эпилепсию, ЧМТ отрицает. | E17: 17 | F17: Ж | G17: Генерализованное тревожное расстройство | H17: F41.1 | I17: F41.1 | J17: — | K17: — | L17: нет | M17: нет | N17: нет | O17: не указано | P17: не указано | Q17: нет | R17: не указано | S17: нет
A18: N017 | B18: P028 | C18: свободный текст | D18: Пациентка Ф. 23 лет обратилась с жалобами на тревогу и напряжение, которые сохраняются несколько месяцев. Хронические заболевания отрицает. Лекарств не принимает. Аллергия: маритупирдин (Авиандр) — сыпь. Беременность отрицает. Алкоголь — не употребляет. Заключение: Генерализованное тревожное расстройство (F41.1). | E18: 23 | F18: Ж | G18: Генерализованное тревожное расстройство | H18: F41.1 | I18: F41.1 | J18: — | K18: — | L18: маритупирдин (Авиандр) — сыпь | M18: нет | N18: нет | O18: не указано | P18: не указано | Q18: не указано | R18: не указано | S18: нет
A19: N018 | B19: P029 | C19: сокращения | D19: Пациентка Я, 39 л., ж. Д-з: F41.1 — Генерализованное тревожное расстройство. Сопут.: —. Терапия: Золофт 50 мг утром. Аллергия: отрицает. Б-ть: нет. Алк.: эпизодически. | E19: 39 | F19: Ж | G19: Генерализованное тревожное расстройство | H19: F41.1 | I19: F41.1 | J19: сертралин | K19: Золофт | L19: нет | M19: нет | N19: нет | O19: не указано | P19: не указано | Q19: не указано | R19: не указано | S19: редко
A20: N019 | B20: P033 | C20: выписной эпикриз | D20: ВЫПИСНОЙ ЭПИКРИЗ Пациентка Ш., возраст 21. Находилась на лечении в дневном стационаре. Клинический диагноз: основной — Генерализованное тревожное расстройство (F41.1). Лекарственная терапия на момент выписки: Ламизил 250 мг. Аллергологический анамнез: без особенностей. Лабораторно: без клинически значимых отклонений. Беременность: нет. Вредные привычки: алкоголь не употребляет. | E20: 21 | F20: Ж | G20: Генерализованное тревожное расстройство | H20: F41.1 | I20: F41.1 | J20: тербинафин | K20: Ламизил | L20: нет | M20: нет | N20: нет | O20: не указано | P20: не указано | Q20: не указано | R20: не указано | S20: нет
